# Promise

Promise 对象用于表示一个异步操作的最终完成（或失败）及其结果值。其中链式写法 和 await async等语法解决了回调地狱问题

## Promise 的三种状态

- pending: 待定状态初始状态,既没有被兑现,也没有被拒绝 (默认状态)
- fulfilled: 表示操作成功完成
- rejected: 意味着操作失败

## Promise 的基本使用

Promise 包括了

传入的函数 executor 自动被执行
resolve 成功的回调函数
reject 失败的回调函数

- 在 new 一个 Promise 时 传入的第一个回调函数为 executor, 会自动执行,并传入 resolve 和 reject 参数

- 每一个 promise都有一个 `then` 方法 可以访问到成功的值和失败的原因.

- 可以通过 resolve 或者 reject 来改变状态,同时调用对应的回调.一个 promise 状态发生修改之后,不能再重新的发生变化.

- 当 executor 发生异常时也会触发 promise 的异常.

```js
const promise = new Promise((resolve, reject) => {
  console.log('executor被自动执行一次');
  resolve();
  // reject();
}).then(res => {
  console.log('请求成功')
}, err => {
  console.log(err, '失败');
})

promise.catch(() => {
  console.log('请求失败');
})

```

resolve 参数传入情况分析

1. 普通的值
2. 一个 promise, 当前的 Promise 的状态会由传入的 Promise 来决定
3. 传入一个对象包括了 then 方法,执行 then 方法,并且由该 then 方法决定后续的状态.

传入 promise 的情况

```js
const newPromise = new Promise((resolve, reject) => {
  console.log('-----------');
  // reject("err message")
  resolve("success message")
})


new Promise((resolve, reject) => {
  console.log('executor');
  resolve(newPromise)
}).then(res => {
  console.log('success', res);
}, err => {
  console.log('error', err);
})

```


## 实例方法

`Promise.prototype.then()`

then() 方法返回一个 Promise 它最多需要有两个参数：Promise 的成功和失败情况的回调函数。

每一个 .then() 方法还会返回一个新生成的 promise 对象，可以被链式调用
```js
// promise.then() 的基本使用
const promise1 = new Promise((resolve, reject) => {
  resolve('success')
})
// 同一个 promise 实例可以被多次调用 then 方法
// 当我们的 promise 变为 fulfilled 状态时 resolve 方法会被执行, 之后 then 方法的成功回调函数也会被执行也会被执行.
promise1.then(res => {
  console.log("res1", res)
})

promise1.then(res => {
  console.log("res2", res)
})
promise.catch(error => {
  console.log(error)
})
```
:::tip
绑定的多个 then 当 promise 状态发生变更时会被一一触发
:::

当 .then() 中缺少能够返回 promise 对象的函数时，链式调用就直接继续进行下一环操作。
因此，链式调用可以在最后一个 .catch() 之前把所有的处理已拒绝状态的回调函数都省略掉。

在没有迫切需要的情况下，可以在最后一个 .catch() 语句时再进行错误处理，这种做法更加简单。

.catch() 其实只是没有给处理已兑现状态的回调函数预留参数位置的 .then() 而已。


`Promise.prototype.catch()`

### `catch()` 方法错误捕获, 其实就是 `then()` 方法只书写第二个方法(reject状态下的回调)

```js
// 情况一: executor 内部发生错误
const promise = new Promise((resolve, reject) => {
  // reject('rejected status')
  throw new Error('rejected status')
})

// 错误捕获方式一:
promise.then(undefined, (err) => {
  console.log(err);
})
// 错误捕获方式二:
// 通过catch方法来传入错误(拒绝)的回调函数
// promise/a+规范
promise.catch(err => {
  console.log("err22", err);
})
```

### `catch()` 捕获 promise 上的错误

```js
const promise = new Promise((resolve, reject) => {
	reject('rejected status')
	// throw new Error('rejected status');
});
promise
	.then((res) => {
		return new Promise((resolve, reject) => {
			reject('error status');
		});
	})
	.catch((err) => {
		// 这里的catch捕获的是promise的错误，不是return返回的新promise
    // 因为 then 方法还没被执行 状态就变为 reject
		console.log('error', err);
  });

```

### 链式调用中的 `.catch()` 方法的运用

```js
var p1 = new Promise(function (resolve, reject) {
	resolve('Success');
});

p1.then(function (value) {
	console.log(value); // "Success!"
	throw 'oh, no!';
})
	.catch(function (e) {
		console.log(e); // "oh, no!"
	})
  // 错误被捕获到之后返回一个新的 promise 实例
	.then(
		function () {
			console.log('after a catch the chain is restored');
		},
		function () {
			console.log('Not fired due to the catch');
		}
	);

// 以下行为与上述相同
p1.then(function (value) {
	console.log(value); // "Success!"
	return Promise.reject('oh, no!');
})
	.catch(function (e) {
		console.log(e); // "oh, no!"
	})
	.then(
		function () {
			console.log('after a catch the chain is restored');
		},
		function () {
			console.log('Not fired due to the catch');
		}
	);
```

### catch() 捕获抛出的错误

```js
// 抛出一个错误，大多数时候将调用 catch 方法
var p1 = new Promise(function(resolve, reject) {
  throw 'Uh-oh!';
});

p1.catch(function(e) {
  console.log(e); // "Uh-oh!"
});

// 在异步函数中抛出的错误不会被 catch 捕获到
var p2 = new Promise(function(resolve, reject) {
  setTimeout(function() {
    throw 'Uncaught Exception!';
  }, 1000);
});

p2.catch(function(e) {
  console.log(e); // 不会执行
});

// 在 resolve() 后面抛出的错误会被忽略
var p3 = new Promise(function(resolve, reject) {
  resolve();
  throw 'Silenced Exception!';
});

p3.catch(function(e) {
   console.log(e); // 不会执行
});

```

`Promise.prototype.finally()`

此方法 不管 promise 的状态如何 是 fulfilled 还是 reject 都会执行指定的回调函数,返回一个 `promise`

```js
// finally 不管promise的状态是fulfilled，还是rejected都会被执行
const promise = new Promise((resolve, reject) =>{
  resolve('aaa')
  // reject('error')
})

promise.then(res => {
  console.log(res);
}).catch(err => {
  console.log(err);
}).finally(() => {
  console.log('finally execute');
})

```


## 链式调用
1. 执行 then catch finally 返回的结果是一个全新的 promise 实例，所以可以链式写下去

2. 下一个 then 中哪个方式会被执行，由上一个 then 中的一个方法执行结果来决定

3. then 的方法的返回值会传递给下一个 then 的 PromiseValue



## 静态方法

`promise.resolve()`

描述: 返回一个解析的 promise 对象

参数: 可以是一个普通对象或者普通值

返回值: 返回一个带着给定值解析过的 promise 对象,如果这个值是一个 promise 对象则返回原本的对象.

```js
// 类方法Promise.resolve
// 1.普通的值
const promise = Promise.resolve({ name: 'cyz', age: xx })
// 相当于
const promise2 = new Promise((resolve, reject) => {
  resolve({ name: 'cyz', age: xx })
})

// 2. 一个 promise 对象
const p = Promise.resolve(promise2);
p.then((res) => {
	console.log('res', res);
});

console.log('p === promise2 ? ' + (p === promise2)); // true
```

`promise.reject(reason)`

参数

reason 表示 Promise 被拒绝的原因

返回值

返回一个 给定原因拒绝的 promise

```js
const promise = Promise.reject("rejected message")

// reject 无论传入什么值都是一样的,生成一个新的promise执行
promise.then(res => {
  console.log('res', res);
}).catch(err => {
  console.log('error',err);
})

```

`promise.all(iterable)`

等待所有的

参数: 传入一个可迭代对象

返回值:
1. 如果传入空的迭代对象,则返回一个已完成的同步 promise 对象
2. 如果传入的参数没有任何的 promise 则返回一个异步完成的 promise
3. 其他情况返回一个待处理的 promise 对象
这个返回的 promise 之后会在所有的 promise 都完成或有一个 promise 失败时异步地变为完成或失败。返回值将会按照参数内的 promise 顺序排列，而不是由调用 promise 的完成顺序决定。

如果参数的迭代对象中有一个 promise 状态变为 reject 则 promise.all() 立即变为失败,不管其他的promise的情况

```js
// 创建多个Promise
const p1 = new Promise((resolve, reject)=>{
  setTimeout(() => {
    resolve(111);
  },1000)
})

const p2 = new Promise((resolve, reject)=> {
  setTimeout(() => {
    reject(222);
  },2000)
})

const p3 = new Promise((resolve, reject) => {
  setTimeout(() => {
    resolve(333)
  }, 3000)
})

// 当所有的Promise都变成fulfilled是，在拿到结果
// 如果有一个Promise变为rejected,那么整个Promise为rejected状态
Promise.all([p1, p2, p3, 'aaa']).then(res => {
  console.log(res);
}).catch(err => {
  console.log('err', err);
})

```

`promise.allSettled(iterable)`

Promise.allSettled() 方法以 promise 组成的可迭代对象作为输入，并且返回一个 Promise 实例。
当输入的所有 promise 都已敲定时（包括传递空的可迭代类型），返回的 promise 将兑现，并带有描述每个 promsie 结果的对象数组

```js
// 创建多个Promise
const p1 = new Promise((resolve, reject)=>{
  setTimeout(() => {
    resolve(111);
  },1000)
})

const p2 = new Promise((resolve, reject)=> {
  setTimeout(() => {
    reject(222);
  },2000)
})

const p3 = new Promise((resolve, reject) => {
  setTimeout(() => {
    resolve(333)
  }, 3000)
})

// 当所有的Promise都变成fulfilled是，在拿到结果
// 如果有一个Promise变为rejected,会保存结果，全部执行完后以数组的形式输出
Promise.allSettled([p1, p2, p3, 'aaa']).then(res => {
  console.log(res);
}).catch(err => {
  console.log('err', err);
})

// 返回值
// [
//   { status: 'fulfilled', value: 111 },
//   { status: 'rejected', reason: 222 },
//   { status: 'fulfilled', value: 333 },
//   { status: 'fulfilled', value: 'aaa' }
// ]

```
返回值:

返回一个数组, 数组中以对象的形式描述每一个 promise 的状态.
对象里的属性包括了
- status 描述 promise 的状态
- value 成功状态下的值
- reason 失败状态下的原因


`promise.race()`

相当于是多个 promise 在竞赛, 第一个状态变为 fulfilled 输出,如果第一个状态是为 rejected 输出报错信息

```js
// 创建多个Promise
const p1 = new Promise((resolve, reject) => {
  setTimeout(() => {
    resolve(111)
  }, 100)
})

const p2 = new Promise((resolve, reject) => {
  setTimeout(() => {
    reject(222)
  }, 500)
})

const p3 = new Promise((resolve, reject) => {
  setTimeout(() => {
    resolve(333)
  }, 3000)
})

// 当有一个Promise变为fulfilled，拿到结果
// race竞赛，最快的那个输出，
// 意外：最快的rejected，输出报错信息
Promise.race([p1, p2, p3])
  .then((res) => {
    console.log(res)
  })
  .catch((err) => {
    console.log('err', err)
  })

```

`promise.any()`

Promise.any() 接收一个由 Promise 所组成的可迭代对象，该方法会返回一个新的 promise，

一旦可迭代对象内的任意一个 promise 变成了兑现状态，那么由该方法所返回的 promise 就会变成兑现状态，

如果全部的 promise 对象变为 rejected 则返回一个 reject 的 promise 对象


```js
// 创建多个Promise
const p1 = new Promise((resolve, reject) => {
  setTimeout(() => {
    resolve(111)
  }, 1000)
})

const p2 = new Promise((resolve, reject) => {
  setTimeout(() => {
    reject(222)
  }, 500)
})

const p3 = new Promise((resolve, reject) => {
  setTimeout(() => {
    resolve(333)
  }, 3000)
})

// 直到一个Promise变为 fulfilled，才拿到结果，只输出一个
Promise.any([p1, p2, p3])
  .then((res) => {
    console.log(res)
  })
  .catch((err) => {
    console.log('err', err)
  })
```

全部 promise 为 reject 那么 返回的 error 为

`err [AggregateError: All promises were rejected]`

